<?xml version='1.0'?>

<robot name="hykabai" xmlns:xacro="http://www.ros.org/wiki/xacro">


  <link name='base_footprint'/>

  <joint name="base_joint" type="fixed">
    <parent link="base_footprint"/>
    <child link="base_link"/>
    <origin xyz="0.0 0.0 0.010" rpy="0 0 0"/>
  </joint>

  <link name='base_link'>
    <pose>0 0 0.01 0 0 0</pose>
    <inertial>
      <mass value="1.5"/>
      <origin xyz="0.0 0 0.025" rpy=" 0 0 0"/>
      <inertia
          ixx="0.01" ixy="0" ixz="0"
          iyy="0.01" iyz="0"
          izz="0.01"
      />
    </inertial>

    <collision name='collision'>
      <origin xyz="0.0 0 0.07" rpy=" 0 0 0"/>
      <geometry>
        <cylinder length=".121" radius=".07"/>
      </geometry>
    </collision>

    <visual name='chassis_visual'>
      <origin xyz="-0.125 -0.075 -0.16" rpy=" 0 0 3.1416"/>
      <geometry>
        <mesh filename="package://hykabai_simulations/meshes/Base.stl" scale="0.001 0.001 0.001"/>
      </geometry>
      <material name="Gray">
        <color rgba="0.5 0.5 0.5 1.0"/>
      </material>
    </visual>

    <collision name='caster_collision'>
      <origin rpy="0 0 0" xyz="0.065 0 0.01"/>
      <geometry>
        <sphere radius="0.01"/>
      </geometry>
      <surface>
        <friction>
          <ode>
            <mu>0.015</mu>
            <mu2>0.005</mu2>
            <slip1>1.0</slip1>
            <slip2>1.0</slip2>
          </ode>
        </friction>
      </surface>
    </collision>

    <visual name='caster_visual'>
      <origin rpy="0 0 0" xyz="0.12 0.073 -0.155"/>
      <geometry>
        <mesh filename="package://hykabai_simulations/meshes/CastorWheel.stl" scale="0.001 0.001 0.001"/>
      </geometry>
    </visual>
  </link>


  <link name="left_wheel">
    <!--origin xyz="0 -188 0.035" rpy="0 1.5707 1.5707"/-->
    <collision name="collision">
      <origin rpy="0 1.5707 1.5707" xyz="0 0 0"/>
      <geometry>
        <cylinder length=".021" radius=".035"/>
      </geometry>
    </collision>
    <visual name="left_wheel_visual">
      <origin rpy="0 3.1416 0" xyz="-0.12 0.16 0.189"/>
      <geometry>
        <mesh filename="package://hykabai_simulations/meshes/LeftWheel.stl" scale="0.001 0.001 0.001"/>
      </geometry>
      <material name="Gray">
        <color rgba="0.5 0.5 0.5 1.0"/>
      </material>
    </visual>
    <inertial>
      <origin rpy="0 1.5707 1.5707" xyz="0 0 0"/>
      <mass value="0.0025"/>
      <cylinder_inertia m="0.01" r="0.035" h="0.021"/>
      <inertia
        ixx="0.001" ixy="0.0" ixz="0.0"
        iyy="0.001" iyz="0.0"
        izz="0.001"/>
    </inertial>
  </link>

  <link name="right_wheel">
    <!--origin xyz="0 188 0.035" rpy="0 1.5707 1.5707"/-->
    <collision name="collision">
      <origin rpy="0 1.57 1.57" xyz="0 0 0"/>
      <geometry>
        <cylinder length=".021" radius=".035"/>
      </geometry>
    </collision>
    <visual name="right_wheel_visual">
      <origin rpy="0 0 0" xyz="0.125 -0.01 -0.189"/>
      <geometry>
        <mesh filename="package://hykabai_simulations/meshes/RightWheel.stl" scale="0.001 0.001 0.001"/>
      </geometry>
      <material name="Gray">
        <color rgba="0.5 0.5 0.5 1.0"/>
      </material>
    </visual>
    <inertial>
      <origin rpy="0 1.5707 1.5707" xyz="0 0 0"/>
      <mass value="0.025"/>
      <cylinder_inertia m="0.01" r="0.035" h="0.021"/>
      <inertia
        ixx="0.001" ixy="0.0" ixz="0.0"
        iyy="0.001" iyz="0.0"
        izz="0.001"/>
    </inertial>
  </link>


  <joint type="continuous" name="left_wheel_joint">
    <origin xyz="0 -0.09 0.025" rpy="0 0 0"/>
    <child link="left_wheel"/>
    <parent link="base_link"/>
    <axis xyz="0 1 0" rpy="0 0 0"/>
    <limit effort="100" velocity="100"/>
    <joint_properties damping="0.0" friction="0.0"/>
  </joint>

  <joint type="continuous" name="right_wheel_joint">
    <origin xyz="0 0.082 0.025" rpy="0 0 0"/>
    <child link="right_wheel"/>
    <parent link="base_link"/>
    <axis xyz="0 1 0" rpy="0 0 0"/>
    <limit effort="100" velocity="100"/>
    <joint_properties damping="0.0" friction="0.0"/>
  </joint>

  <gazebo>
        <plugin name='diff_drive' filename='libgazebo_ros_diff_drive.so'>
    
    
            <!-- Wheel Information -->
            <leftJoint>left_wheel_joint</leftJoint>
            <rightJoint>right_wheel_joint</rightJoint>
            <wheelSeparation>0.14</wheelSeparation>
            <wheel_diameter>0.07</wheel_diameter>
	    <wheelDiameter>0.07</wheelDiameter>
    

            <!-- Limits -->
            <max_wheel_torque>150</max_wheel_torque>
            <max_wheel_acceleration>2.0</max_wheel_acceleration>
	    <wheelAcceleration>1.0</wheelAcceleration>
	    <wheelTorque>1.0</wheelTorque>
    

            <!-- Output -->
            <odometry_frame>odom</odometry_frame>
            <robot_base_frame>base_link</robot_base_frame>

            <publish_odom>true</publish_odom>
            <publish_odom_tf>true</publish_odom_tf>
	    <publishOdomTF>true</publishOdomTF>
            

	        <commandTopic>cmd_vel</commandTopic>
		    <odometryTopic>odom</odometryTopic>
		    <odometryFrame>odom</odometryFrame>
		    <odometrySource>world</odometrySource>
		    
		    <robotBaseFrame>base_footprint</robotBaseFrame>
		    <publishWheelTF>true</publishWheelTF>
		    <publishTf>true</publishTf>
		    <publishWheelJointState>true</publishWheelJointState>
		    <legacyMode>false</legacyMode>
		    <updateRate>30</updateRate>
    
    
        </plugin>
  </gazebo>

  <joint name="lidar_joint" type="fixed">
    <axis xyz="0 1 0" />
    <origin xyz="0 0 0" rpy="0 0 0"/>
    <parent link="base_link"/>
    <child link="rplidar_link"/>
  </joint>
  <link name="rplidar_link">
    <collision>
      <origin xyz="0 0 0.05" rpy="0 0 0"/>
      <geometry>
    <box size="0.1 0.1 0.1"/>
      </geometry>
    </collision>
  </link>
  <gazebo reference="rplidar_link">
        <material>Gazebo/Red</material>
 
        <sensor name="laser" type="ray">
            <pose> 0 0 0 0 0 0 </pose>
            <visualize>true</visualize>
            <update_rate>10</update_rate>
            <ray>
                <scan>
                    <horizontal>
                        <samples>360</samples>
                        <min_angle>-3.14</min_angle>
                        <max_angle>3.14</max_angle>
                    </horizontal>
                </scan>
                <range>
                    <min>0.15</min>
                    <max>12</max>
                </range>
            </ray>
            <plugin name="laser_controller" filename="libgazebo_ros_laser.so">
                <ros>
                    <argument>~/out:=scan</argument>
                </ros>
                <topicName>/scan</topicName>
                <output_type>sensor_msgs/LaserScan</output_type>
                <frameName>rplidar_link</frameName>
            </plugin>
        </sensor>
    </gazebo>



</robot>
	
	
