<?xml version='1.0'?>

<robot name="hykabai" xmlns:xacro="http://www.ros.org/wiki/xacro">


  <link name='base_footprint'/>

  <joint name="base_joint" type="fixed">
    <parent link="base_footprint"/>
    <child link="base_link"/>
    <origin xyz="0.0 0.0 0.010" rpy="0 0 0"/>
  </joint>

  <link name='base_link'>
    <pose>0 0 0.01 0 0 0</pose>
    <inertial>
      <mass value="2.4"/>
      <origin xyz="0.0 0 0.045" rpy=" 0 0 0"/>
      <inertia
          ixx="0.0001" ixy="0" ixz="0"
          iyy="0.0001" iyz="0"
          izz="0.0001"
      />
    </inertial>

    <collision name='collision'>
      <origin xyz="0.0 0 0.07" rpy=" 0 0 0"/>
      <geometry>
        <cylinder length=".121" radius=".07"/>
      </geometry>
    </collision>

    <visual name='chassis_visual'>
      <origin xyz="-0.125 -0.075 -0.16" rpy=" 0 0 3.1416"/>
      <geometry>
        <mesh filename="package://hykabai_simulations/meshes/Base.stl" scale="0.001 0.001 0.001"/>
      </geometry>
      <material name="Gray">
        <color rgba="0.5 0.5 0.5 1.0"/>
      </material>
    </visual>

    <collision name='caster_collision'>
      <origin rpy="0 0 0" xyz="0.065 0 0.01"/>
      <geometry>
        <sphere radius="0.01"/>
      </geometry>
      <surface>
        <friction>
          <ode>
            <mu>0</mu>
            <mu2>0</mu2>
            <slip1>1.0</slip1>
            <slip2>1.0</slip2>
          </ode>
        </friction>
      </surface>
    </collision>

    <visual name='caster_visual'>
      <origin rpy="0 0 0" xyz="0.12 0.073 -0.155"/>
      <geometry>
        <mesh filename="package://hykabai_simulations/meshes/CastorWheel.stl" scale="0.001 0.001 0.001"/>
      </geometry>
    </visual>
  </link>


  <link name="left_wheel">
    <!--origin xyz="0 -188 0.035" rpy="0 1.5707 1.5707"/-->
    <collision name="collision">
      <origin rpy="0 1.5707 1.5707" xyz="0 0 0"/>
      <geometry>
        <cylinder length=".021" radius=".035"/>
      </geometry>
    </collision>
    <visual name="left_wheel_visual">
      <origin rpy="0 3.1416 0" xyz="-0.12 0.16 0.189"/>
      <geometry>
        <mesh filename="package://hykabai_simulations/meshes/LeftWheel.stl" scale="0.001 0.001 0.001"/>
      </geometry>
      <material name="Gray">
        <color rgba="0.5 0.5 0.5 1.0"/>
      </material>
    </visual>
    <inertial>
      <origin rpy="0 1.5707 1.5707" xyz="0 0 0.035"/>
      <mass value="0.01"/>
      <cylinder_inertia m="0.01" r="0.035" h="0.021"/>
      <inertia
        ixx="0.001" ixy="0.0" ixz="0.0"
        iyy="0.001" iyz="0.0"
        izz="0.001"/>
    </inertial>
  </link>

  <link name="right_wheel">
    <!--origin xyz="0 188 0.035" rpy="0 1.5707 1.5707"/-->
    <collision name="collision">
      <origin rpy="0 1.57 1.57" xyz="0 0 0"/>
      <geometry>
        <cylinder length=".021" radius=".035"/>
      </geometry>
    </collision>
    <visual name="right_wheel_visual">
      <origin rpy="0 0 0" xyz="0.125 -0.01 -0.189"/>
      <geometry>
        <mesh filename="package://hykabai_simulations/meshes/RightWheel.stl" scale="0.001 0.001 0.001"/>
      </geometry>
      <material name="Gray">
        <color rgba="0.5 0.5 0.5 1.0"/>
      </material>
    </visual>
    <inertial>
      <origin rpy="0 1.5707 1.5707" xyz="0 0 0.035"/>
      <mass value="0.01"/>
      <cylinder_inertia m="0.01" r="0.035" h="0.021"/>
      <inertia
        ixx="0.001" ixy="0.0" ixz="0.0"
        iyy="0.001" iyz="0.0"
        izz="0.001"/>
    </inertial>
  </link>


  <joint type="continuous" name="left_wheel_hinge">
    <origin xyz="0 -0.09 0.025" rpy="0 0 0"/>
    <child link="left_wheel"/>
    <parent link="base_link"/>
    <axis xyz="0 1 0" rpy="0 0 0"/>
    <limit effort="100" velocity="100"/>
    <joint_properties damping="0.0" friction="0.0"/>
  </joint>

  <joint type="continuous" name="right_wheel_hinge">
    <origin xyz="0 0.082 0.025" rpy="0 0 0"/>
    <child link="right_wheel"/>
    <parent link="base_link"/>
    <axis xyz="0 1 0" rpy="0 0 0"/>
    <limit effort="100" velocity="100"/>
    <joint_properties damping="0.0" friction="0.0"/>
  </joint>




</robot>
	
	
